<sdf version='1.6'>
  <model name='uniped'>
    <link name='torso'>
      <pose frame=''>0 0 0 0 -0 0</pose>
      <inertial>
        <pose frame=''>0 0 1.55 0 -0 0</pose>
        <mass>1</mass>
        <inertia>
          <ixx>0.0483333</ixx>
          <ixy>0</ixy>
          <ixz>0</ixz>
          <iyy>0.0816667</iyy>
          <iyz>0</iyz>
          <izz>0.0483333</izz>
        </inertia>
      </inertial>
      <collision name='torso_collision'>
        <pose frame=''>0 0 1.55 0 -0 0</pose>
        <geometry>
          <box>
            <size>0.7 0.3 0.7</size>
          </box>
        </geometry>
        <surface>
          <contact>
            <ode/>
          </contact>
          <friction>
            <ode/>
          </friction>
        </surface>
      </collision>
      <visual name='torso_visual'>
        <pose frame=''>0 0 0.35 0 -0 0</pose>
        <geometry>
          <box>
            <size>0.7 0.3 0.7</size>
          </box>
        </geometry>
        <material>
          <script>
            <name>Gazebo/Blue</name>
            <uri>file://media/materials/scripts/gazebo.material</uri>
          </script>
        </material>
      </visual>
      <gravity>1</gravity>
      <velocity_decay/>
    </link>
    <link name='tigh'>
      <pose frame=''>0 0 -0.35 0 -0 0</pose>
      <inertial>
        <pose frame=''>0 0 -0.25 0 -0 0</pose>
        <mass>1</mass>
        <inertia>
          <ixx>0.0241667</ixx>
          <ixy>0</ixy>
          <ixz>0</ixz>
          <iyy>0.0241667</iyy>
          <iyz>0</iyz>
          <izz>0.00666667</izz>
        </inertia>
      </inertial>
      <collision name='tigh_collision'>
        <pose frame=''>0 0 -0.25 0 -0 0</pose>
        <geometry>
          <box>
            <size>0.2 0.2 0.5</size>
          </box>
        </geometry>
        <surface>
          <contact>
            <ode/>
          </contact>
          <friction>
            <ode>
              <mu>0.2</mu>
              <mu2>0.2</mu2>
            </ode>
          </friction>
        </surface>
      </collision>
      <visual name='tigh_visual'>
        <pose frame=''>0 0 -0.25 0 -0 0</pose>
        <geometry>
          <box>
            <size>0.2 0.2 0.5</size>
          </box>
        </geometry>
        <material>
          <script>
            <name>Gazebo/White</name>
            <uri>file://media/materials/scripts/gazebo.material</uri>
          </script>
        </material>
      </visual>
      <gravity>1</gravity>
      <velocity_decay/>
    </link>
    <joint name='hip' type='revolute'>
      <child>tigh</child>
      <parent>torso</parent>
      <axis>
        <xyz>1 0 0</xyz>
        <limit>
          <lower>-1e+16</lower>
          <upper>1e+16</upper>
        </limit>
        <dynamics>
          <damping>0.7</damping>
          <friction>0</friction>
          <spring_reference>0</spring_reference>
          <spring_stiffness>0</spring_stiffness>
        </dynamics>
        <use_parent_model_frame>1</use_parent_model_frame>
      </axis>
    </joint>
  </model>
</sdf>
