<?xml version="1.0" encoding="utf-8"?>
<!-- =================================================================================== -->
<!-- |    This document was autogenerated by xacro from uniped.xacro                   | -->
<!-- |    EDITING THIS FILE BY HAND IS NOT RECOMMENDED                                 | -->
<!-- =================================================================================== -->
<!-- Revolute-Revolute Manipulator -->
<robot name="uniped">
  <!-- length of the foot -->
  <!-- use gravity flag -->
  <!-- ros_control plugin -->
  <gazebo>
    <plugin filename="libgazebo_ros_control.so" name="gazebo_ros_control">
      <robotNamespace>/rrbot</robotNamespace>
      <robotSimType>gazebo_ros_control/DefaultRobotHWSim</robotSimType>
    </plugin>
  </gazebo>
  <!-- Torso -->
  <gazebo reference="torso">
    <material>Gazebo/Orange</material>
  </gazebo>
  <!-- tigh -->
  <gazebo reference="tigh">
    <mu1>0.2</mu1>
    <mu2>0.2</mu2>
    <material>Gazebo/White</material>
  </gazebo>
  <!-- calf -->
  <gazebo reference="calf">
    <mu1>0.2</mu1>
    <mu2>0.2</mu2>
    <material>Gazebo/Orange</material>
  </gazebo>
  <!-- foot -->
  <gazebo reference="foot">
    <mu1>0.2</mu1>
    <mu2>0.2</mu2>
    <material>Gazebo/White</material>
  </gazebo>
  <material name="black">
    <color rgba="0.0 0.0 0.0 1.0"/>
  </material>
  <material name="blue">
    <color rgba="0.0 0.0 0.8 1.0"/>
  </material>
  <material name="green">
    <color rgba="0.0 0.8 0.0 1.0"/>
  </material>
  <material name="grey">
    <color rgba="0.2 0.2 0.2 1.0"/>
  </material>
  <material name="orange">
    <color rgba="1.0 0.423529411765 0.0392156862745 1.0"/>
  </material>
  <material name="brown">
    <color rgba="0.870588235294 0.811764705882 0.764705882353 1.0"/>
  </material>
  <material name="red">
    <color rgba="0.8 0.0 0.0 1.0"/>
  </material>
  <material name="white">
    <color rgba="1.0 1.0 1.0 1.0"/>
  </material>
  <!-- Torso Link -->
  <link name="torso">
    <collision>
      <origin rpy="0 0 0" xyz="0 0 1.55"/>
      <geometry>
        <box size="0.7 0.3 0.7"/>
      </geometry>
    </collision>
    <visual>
      <origin rpy="0 0 0" xyz="0 0 1.55"/>
      <geometry>
        <box size="0.7 0.3 0.7"/>
      </geometry>
      <material name="blue"/>
    </visual>
    <inertial>
      <origin rpy="0 0 0" xyz="0 0 1.55"/>
      <mass value="1"/>
      <inertia ixx="0.0483333333333" ixy="0.0" ixz="0.0" iyy="0.0816666666667" iyz="0.0" izz="0.0483333333333"/>
    </inertial>
  </link>
  <joint name="hip" type="continuous">
    <parent link="torso"/>
    <child link="tigh"/>
    <origin rpy="0 0 0" xyz="0 0 1.2"/>
    <axis xyz="1 0 0"/>
    <dynamics damping="0.7"/>
  </joint>
  <!-- Tigh Link -->
  <link name="tigh">
    <collision>
      <origin rpy="0 0 0" xyz="0 0 -0.25"/>
      <geometry>
        <box size="0.2 0.2 0.5"/>
      </geometry>
    </collision>
    <visual>
      <origin rpy="0 0 0" xyz="0 0 -0.25"/>
      <geometry>
        <box size="0.2 0.2 0.5"/>
      </geometry>
      <material name="white"/>
    </visual>
    <inertial>
      <origin rpy="0 0 0" xyz="0 0 -0.25"/>
      <mass value="1"/>
      <inertia ixx="0.0241666666667" ixy="0.0" ixz="0.0" iyy="0.0241666666667" iyz="0.0" izz="0.00666666666667"/>
    </inertial>
  </link>
  <joint name="knee" type="continuous">
    <parent link="tigh"/>
    <child link="calf"/>
    <origin rpy="0 0 0" xyz="0 0 -0.5"/>
    <axis xyz="1 0 0"/>
    <dynamics damping="0.7"/>
  </joint>
  <link name="calf">
    <collision>
      <origin rpy="0 0 0" xyz="0 0 -0.25"/>
      <geometry>
        <box size="0.2 0.2 0.5"/>
      </geometry>
    </collision>
    <visual>
      <origin rpy="0 0 0" xyz="0 0 -0.25"/>
      <geometry>
        <box size="0.2 0.2 0.5"/>
      </geometry>
      <material name="blue"/>
    </visual>
    <inertial>
      <origin rpy="0 0 0" xyz="0 0 -0.25"/>
      <mass value="1"/>
      <inertia ixx="0.0241666666667" ixy="0.0" ixz="0.0" iyy="0.0241666666667" iyz="0.0" izz="0.00666666666667"/>
    </inertial>
  </link>
  <joint name="ankle" type="continuous">
    <parent link="calf"/>
    <child link="foot"/>
    <origin rpy="0 0 0" xyz="0 0 -0.5"/>
    <axis xyz="1 0 0"/>
    <dynamics damping="0.7"/>
  </joint>
  <link name="foot">
    <collision>
      <origin rpy="0 0 0" xyz="0 0.05 -0.1"/>
      <geometry>
        <box size="0.3 0.3 0.2"/>
      </geometry>
    </collision>
    <visual>
      <origin rpy="0 0 0" xyz="0 0.05 -0.1"/>
      <geometry>
        <box size="0.3 0.3 0.2"/>
      </geometry>
      <material name="white"/>
    </visual>
    <inertial>
      <origin rpy="0 0 0" xyz="0 0.05 -0.1"/>
      <mass value="1"/>
      <inertia ixx="0.0108333333333" ixy="0.0" ixz="0.0" iyy="0.0108333333333" iyz="0.0" izz="0.015"/>
    </inertial>
  </link>
  <gazebo reference="torso">
    <turnGravityOff>1</turnGravityOff>
  </gazebo>
  <gazebo reference="tigh">
    <turnGravityOff>1</turnGravityOff>
  </gazebo>
  <gazebo reference="calf">
    <turnGravityOff>1</turnGravityOff>
  </gazebo>
  <gazebo reference="foot">
    <turnGravityOff>1</turnGravityOff>
  </gazebo>
</robot>

